Workbook

Sheet Data
A1: Id | B1: Godzina rozpoczęcia | C1: Godzina ukończenia | D1: Adres e-mail | E1: Nazwa | F1: How old are you? | G1: What is your highest level of education? | H1: Is your educational background related to STEM (Science, Technology, Engineering, Mathematics)? | I1: What is your work arrangement? | J1: work arrangement ordinal | K1: In which industry/domain does your company operate (e.g., finance, game development, enterprise software)? | L1: What is the size of your company? | M1: How long have you been working in software development? | N1: What is your professional role? | O1: How big is your team? | P1: What types of projects do you most often work on? | Q1: Column | R1: How frequently do you experience interruptions in a typical workday? | S1: Frequency_ordinal | T1: What are the most common sources of interruptions in your work? | U1: What are these interruptions usually about? | V1: Who interrupts you most often at work? | W1: How much do interruptions disrupt your focus and workflow? (1 = not disruptive at all, 5 = very disruptive) | X1: How quickly do you switch to handling the new "interrupting " task? | Y1: Time_to_regain_focus_ordinal | Z1: On average, how long does it take you to regain full focus after an interruption? | AA1: Do you use any techniques to reduce interruptions (e.g., focus time, “do not disturb” status)? | AB1: What methods do you personally use to reduce or manage interruptions during your work? (max. 3) | AC1: How effective do you consider these methods to be? (1 = ineffective, 5 = very effective) | AD1: How do you rate your productivity in a typical workday? (1 = very low, 5 = very high) | AE1: How often do you feel that interruptions negatively affect the quality of your work? (1 = never, 5 - very often) | AF1: How satisfied are you with your job overall (job satisfaction)? (1 = very dissatisfied, 5 = very satisfied) | AG1: What actions could you take to better manage or reduce unplanned interruptions in your workday? (max 3) | AH1: What actions could your team take to better manage or reduce unplanned interruptions in your workday? (max 3) | AI1: What actions could your company take to better manage or reduce unplanned interruptions in your workday? (max 3) | AJ1: Would you be willing to participate in the next stage of the study — an interview? | AK1: Please provide an email address where we can contact you regarding an interview.
A2: 1 | B2: 45996.425 | C2: 45996.428 | D2: anonymous | F2: 18 - 24 | G2: Master’s degree | H2: Yes | I2: Hybrid | J2: 2 | K2: Finanance | L2: 501–5000 | M2: 1–3 years | N2: Data Scientist | O2: 8–12 people | P2: Research & development (R&D);Short-term / contract project; | Q2: I understand the definition of interruption | R2: 3–6 times | S2: 2 | T2: Team chats and messages (e.g., Teams, Slack, Jira);Meetings and quick conversations (e.g., ad-hoc calls, unexpected discussions); | U2: Implementation details; | V2: Colleagues at the same level (team members / peers) | W2: 2 | X2: 1 - 15 minutes | Y2: 2 | Z2: 1 - 15 minutes | AA2: No | AD2: 3 | AE2: 2 | AF2: 3 | AJ2: No
A3: 2 | B3: 45996.451 | C3: 45996.456 | D3: anonymous | F3: 30 - 34 | G3: Master’s degree | H3: Yes | I3: Hybrid | J3: 2 | K3: FINANCE | L3: More than 5000 | M3: 4–7 years | N3: Developer | O3: 8–12 people | P3: Internal product (e.g., company systems); | Q3: I understand the definition of interruption | R3: 3–6 times | S3: 2 | T3: Team chats and messages (e.g., Teams, Slack, Jira);Meetings and quick conversations (e.g., ad-hoc calls, unexpected discussions);System notifications and emails (alerts, reminders, work messages);Self-interruptions (voluntary context switching) — switching tasks on your own initiative (e.g., technical blockage, loss of focus); | U3: Technical questions or code questions;Notifications from communication tools;Organizational matters (e.g., meetings, planning); | V3: Colleagues at the same level (team members / peers) | W3: 2 | X3: 1 - 15 minutes | Y3: 2 | Z3: 15 - 30 minutes | AA3: Sometimes | AB3: NOT DISTURB STATUS IN TEAMS, IGNORING MESSAGES AFTER 12 | AC3: 2 | AD3: 4 | AE3: 3 | AF3: 4 | AJ3: No
A4: 3 | B4: 45996.497 | C4: 45996.499 | D4: anonymous | F4: 18 - 24 | G4: High school | H4: Yes | I4: On-site | J4: 3 | K4: Finance | L4: More than 5000 | M4: 1–3 years | N4: IT Manager | O4: 2–3 people | P4: Internal product (e.g., company systems);Commercial product (external client); | Q4: I understand the definition of interruption | R4: Less than 3 times per day | S4: 1 | T4: Meetings and quick conversations (e.g., ad-hoc calls, unexpected discussions); | U4: Code review; | V4: People in supporting or junior roles (e.g., less experienced team members) | W4: 4 | X4: 1 - 15 minutes | Y4: 2 | Z4: 30 - 60 minutes | AA4: Yes | AB4: . | AC4: 5 | AD4: 5 | AE4: 5 | AF4: 5 | AJ4: Yes
A5: 4 | B5: 45996.508 | C5: 45996.51 | D5: anonymous | F5: 18 - 24 | G5: High school | H5: Yes | I5: Hybrid | J5: 2 | K5: Office | L5: 101–500 | M5: 1–3 years | N5: IT Consultant | O5: 4–7 people | P5: Internal product (e.g., company systems); | Q5: I understand the definition of interruption | R5: Less than 3 times per day | S5: 1 | T5: Team chats and messages (e.g., Teams, Slack, Jira);Work environment (e.g., office noise, conversations, working on multiple projects simultaneously); | U5: Requests for help with environment issues; | V5: Colleagues at the same level (team members / peers) | W5: 4 | X5: 1 - 15 minutes | Y5: 2 | Z5: 15 - 30 minutes | AA5: No | AD5: 4 | AE5: 4 | AF5: 2 | AJ5: No
A6: 5 | B6: 45996.505 | C6: 45996.51 | D6: anonymous | F6: 18 - 24 | G6: High school | H6: Yes | I6: Hybrid | J6: 2 | K6: Finance | L6: 101–500 | M6: 1–3 years | N6: Tester | O6: 2–3 people | P6: Commercial product (external client); | Q6: I understand the definition of interruption | R6: 3–6 times | S6: 2 | T6: Team chats and messages (e.g., Teams, Slack, Jira); | U6: Implementation details; | V6: People in supporting or junior roles (e.g., less experienced team members) | W6: 3 | X6: 1 - 15 minutes | Y6: 2 | Z6: 15 - 30 minutes | AA6: No | AD6: 3 | AE6: 2 | AF6: 4 | AG6: 1. Block dedicated focus time on my calendar and mute non-critical notifications during those periods. 2. Set clearer expectations with colleagues about my availability and preferred communication channels. 3. Prioritize tasks at the start of each day so I can quickly refocus after any unavoidable interruptions | AH6: 1. Establish shared team norms for communication, including when to use chat, email, or meetings. 2. Consolidate non-urgent requests into daily or weekly sync points instead of ad-hoc interruptions. 3. Improve documentation and knowledge-sharing so fewer urgent “quick questions” arise. | AI6: 1. Promote a company-wide culture that respects focus time and minimizes unnecessary context switching. 2. Provide tools or processes that streamline task management and reduce last-minute escalations. 3. Align priorities and planning more consistently across departments to prevent unexpected work requests. | AJ6: No
A7: 6 | B7: 45996.75 | C7: 45996.753 | D7: anonymous | F7: 18 - 24 | G7: Master’s degree | H7: Yes | I7: Hybrid | J7: 2 | K7: finance | L7: 21–100 | M7: Less than 1 year | N7: IT Consultant | O7: 4–7 people | P7: Internal product (e.g., company systems);Commercial product (external client); | Q7: I understand the definition of interruption | R7: Less than 3 times per day | S7: 1 | T7: Meetings and quick conversations (e.g., ad-hoc calls, unexpected discussions);Team chats and messages (e.g., Teams, Slack, Jira); | U7: Notifications from communication tools;Requests for help with environment issues; | V7: Manager / product owner (formal supervisor or decision-maker) | W7: 3 | X7: 1 - 15 minutes | Y7: 2 | Z7: 15 - 30 minutes | AA7: No | AD7: 3 | AE7: 5 | AF7: 4 | AJ7: No
A8: 7 | B8: 45996.754 | C8: 45996.757 | D8: anonymous | F8: 18 - 24 | G8: Bachelor’s degree | H8: Yes | I8: Remote | J8: 1 | K8: Finance | L8: 101–500 | M8: Less than 1 year | N8: Tester | O8: 2–3 people | P8: Internal product (e.g., company systems); | Q8: I understand the definition of interruption | R8: 7–10 times | S8: 3 | T8: Team chats and messages (e.g., Teams, Slack, Jira);System notifications and emails (alerts, reminders, work messages);Work environment (e.g., office noise, conversations, working on multiple projects simultaneously); | U8: Implementation details;Notifications from communication tools; | V8: Manager / product owner (formal supervisor or decision-maker) | W8: 4 | X8: 1 - 15 minutes | Y8: 2 | Z8: 1 - 15 minutes | AA8: Sometimes | AB8: “do not disturb” | AC8: 3 | AD8: 3 | AE8: 5 | AF8: 2 | AJ8: No
A9: 8 | B9: 45996.758 | C9: 45996.76 | D9: anonymous | F9: 25 - 29 | G9: PhD | H9: Yes | I9: Remote | J9: 1 | K9: Game Dev | L9: 501–5000 | M9: 4–7 years | N9: Developer | O9: 8–12 people | P9: Commercial product (external client);Short-term / contract project;Research & development (R&D); | Q9: I understand the definition of interruption | R9: More than 10 times | S9: 4 | T9: Team chats and messages (e.g., Teams, Slack, Jira);Meetings and quick conversations (e.g., ad-hoc calls, unexpected discussions);System notifications and emails (alerts, reminders, work messages); | U9: Technical questions or code questions;Implementation details;Requests for help with environment issues;Code review;Notifications from communication tools;Organizational matters (e.g., meetings, planning); | V9: People in supporting or junior roles (e.g., less experienced team members) | W9: 4 | X9: 1 - 15 minutes | Y9: 2 | Z9: 30 - 60 minutes | AA9: Yes | AB9: Słuchawki z aktywnym tłumieniem szumów w celu wyciszenia hałasu, sztywne planowanie kolejności wykonywania zadań każdego dnia | AC9: 4 | AD9: 4 | AE9: 5 | AF9: 5 | AJ9: No
A10: 9 | B10: 45996.8 | C10: 45996.805 | D10: anonymous | F10: 25 - 29 | G10: Master’s degree | H10: Yes | I10: Hybrid | J10: 2 | K10: My company is operating in finance | L10: 21–100 | M10: 1–3 years | N10: Tester | O10: 4–7 people | P10: Short-term / contract project; | Q10: I understand the definition of interruption | R10: 3–6 times | S10: 2 | T10: Meetings and quick conversations (e.g., ad-hoc calls, unexpected discussions);System notifications and emails (alerts, reminders, work messages);Team chats and messages (e.g., Teams, Slack, Jira); | U10: Task status reminders;Requests for help with environment issues;Implementation details; | V10: Manager / product owner (formal supervisor or decision-maker) | W10: 3 | X10: 30 - 60 minutes | Y10: 4 | Z10: 15 - 30 minutes | AA10: No | AD10: 4 | AE10: 2 | AF10: 4 | AG10: Set clear focus blocks by scheduling dedicated time for deep work and temporarily muting non-urgent notifications. | AH10: Agree on shared communication norms, including expected response times and when to use specific channels. | AI10: Set organization-wide communication guidelines to reduce unnecessary pings and clarify expected response times. | AJ10: No
A11: 10 | B11: 45996.98 | C11: 45996.984 | D11: anonymous | F11: 18 - 24 | G11: Master’s degree | H11: Yes | I11: Remote | J11: 1 | K11: Fiance | L11: Under 20 employees | M11: 4–7 years | N11: Tester | O11: 4–7 people | P11: Internal product (e.g., company systems); | Q11: I understand the definition of interruption | R11: 3–6 times | S11: 2 | T11: System notifications and emails (alerts, reminders, work messages); | U11: Implementation details; | V11: Manager / product owner (formal supervisor or decision-maker) | W11: 5 | X11: 1 - 15 minutes | Y11: 2 | Z11: 15 - 30 minutes | AA11: Yes | AB11: I use the app on my phone | AC11: 4 | AD11: 4 | AE11: 4 | AF11: 4 | AG11: I plan my tasks, mute notifications, and set specific times to respond to messages. | AH11: use shared calendars for focus time | AI11: The company could introduce meeting free hours | AJ11: No
A12: 11 | B12: 45997.016 | C12: 45997.021 | D12: anonymous | F12: 18 - 24 | G12: High school | H12: Yes | I12: On-site | J12: 3 | K12: Finance | L12: 21–100 | M12: 1–3 years | N12: Developer | O12: 4–7 people | P12: Internal product (e.g., company systems);Short-term / contract project; | Q12: I understand the definition of interruption | R12: 7–10 times | S12: 3 | T12: Team chats and messages (e.g., Teams, Slack, Jira);System notifications and emails (alerts, reminders, work messages);Self-interruptions (voluntary context switching) — switching tasks on your own initiative (e.g., technical blockage, loss of focus); | U12: Technical questions or code questions; | V12: Colleagues at the same level (team members / peers) | W12: 4 | X12: 1 - 15 minutes | Y12: 2 | Z12: 15 - 30 minutes | AA12: No | AD12: 4 | AE12: 5 | AF12: 4 | AG12: Turn of my phone | AH12: Don't call me during if something is not important | AI12: Give workers personal rooms to work | AJ12: No
A13: 12 | B13: 45997.636 | C13: 45997.643 | D13: anonymous | F13: 18 - 24 | G13: High school | H13: Yes | I13: Hybrid | J13: 2 | K13: finance | L13: 101–500 | M13: 1–3 years | N13: Developer | O13: 2–3 people | P13: Short-term / contract project; | Q13: I understand the definition of interruption | R13: 3–6 times | S13: 2 | T13: Team chats and messages (e.g., Teams, Slack, Jira);Self-interruptions (voluntary context switching) — switching tasks on your own initiative (e.g., technical blockage, loss of focus); | U13: Task status reminders;Organizational matters (e.g., meetings, planning); | V13: Colleagues at the same level (team members / peers) | W13: 3 | X13: 1 - 15 minutes | Y13: 2 | Z13: 15 - 30 minutes | AA13: Yes | AB13: do not disturb | AC13: 4 | AD13: 4 | AE13: 2 | AF13: 4 | AG13: turn on: do not disturb in my phone | AH13: talk to each other and try to change that | AI13: . | AJ13: No
A14: 13 | B14: 45997.995 | C14: 45997.996 | D14: anonymous | F14: 18 - 24 | G14: Bachelor’s degree | H14: No | I14: On-site | J14: 3 | K14: Salwa | L14: 101–500 | M14: Less than 1 year | N14: Tester | O14: 4–7 people | P14: Internal product (e.g., company systems); | Q14: I understand the definition of interruption | R14: 3–6 times | S14: 2 | T14: System notifications and emails (alerts, reminders, work messages); | U14: Technical questions or code questions; | V14: Manager / product owner (formal supervisor or decision-maker) | W14: 4 | X14: 15 - 30 minutes | Y14: 3 | Z14: Immediately | AA14: No | AD14: 5 | AE14: 3 | AF14: 1 | AJ14: No
A15: 14 | B15: 45998.089 | C15: 45998.094 | D15: anonymous | F15: 18 - 24 | G15: High school | H15: No | I15: Hybrid | J15: 2 | K15: social media | L15: Under 20 employees | M15: Less than 1 year | N15: Tester | O15: 1 person (solo) | P15: Commercial product (external client); | Q15: I understand the definition of interruption | R15: 3–6 times | S15: 2 | T15: Team chats and messages (e.g., Teams, Slack, Jira);System notifications and emails (alerts, reminders, work messages);Self-interruptions (voluntary context switching) — switching tasks on your own initiative (e.g., technical blockage, loss of focus); | U15: Notifications from communication tools;Task status reminders;Organizational matters (e.g., meetings, planning); | V15: family | W15: 3 | X15: 15 - 30 minutes | Y15: 3 | Z15: 15 - 30 minutes | AA15: Yes | AB15: do not disturb status | AC15: 3 | AD15: 3 | AE15: 5 | AF15: 4 | AJ15: No
A16: 15 | B16: 45998.766 | C16: 45998.769 | D16: anonymous | F16: 18 - 24 | G16: Bachelor’s degree | H16: Yes | I16: On-site | J16: 3 | K16: finance | L16: 21–100 | M16: 1–3 years | N16: IT Consultant | O16: 2–3 people | P16: Internal product (e.g., company systems); | Q16: I understand the definition of interruption | R16: 3–6 times | S16: 2 | T16: Team chats and messages (e.g., Teams, Slack, Jira); | U16: Technical questions or code questions; | V16: Colleagues at the same level (team members / peers) | W16: 3 | X16: 1 - 15 minutes | Y16: 2 | Z16: 1 - 15 minutes | AA16: No | AD16: 4 | AE16: 3 | AF16: 5 | AG16: silence notifications | AH16: use shared calendars | AI16: set clear communication rules | AJ16: No
A17: 16 | B17: 45998.768 | C17: 45998.771 | D17: anonymous | F17: 30 - 34 | G17: Master’s degree | H17: Yes | I17: On-site | J17: 3 | K17: finance | L17: 101–500 | M17: 4–7 years | N17: IT Manager | O17: 13–20 people | P17: Internal product (e.g., company systems); | Q17: I understand the definition of interruption | R17: 7–10 times | S17: 3 | T17: Work environment (e.g., office noise, conversations, working on multiple projects simultaneously); | U17: Technical questions or code questions;Code review; | V17: Other departments (HR, sales, marketing) | W17: 3 | X17: 1 - 15 minutes | Y17: 2 | Z17: 15 - 30 minutes | AA17: No | AD17: 5 | AE17: 5 | AF17: 5 | AG17: Set dedicated focus time blocks with “Do Not Disturb” enabled to minimize spontaneous interruptions during deep-work tasks. Improve daily planning and prioritization, including reserving buffer time for unexpected issues to reduce context-switching. Communicate availability proactively so teammates know when I’m open for questions and when I need uninterrupted time. | AH17: 1. Establish clear communication windows for questions and discussions to avoid constant context switching. 2. Improve task planning and backlog refinement to reduce last-minute surprises. 3. Use a shared channel or ticketing system for non-urgent requests instead of direct ad-hoc messages. | AI17: 1. Provide guidelines for communication expectations, including response times and “focus time” etiquette. 2. Invest in better tooling and automation to reduce manual work and unexpected operational issues. 3. Ensure realistic workload and clearer prioritization so teams can focus without frequent unplanned shifts. | AJ17: No
A18: 17 | B18: 45998.795 | C18: 45998.796 | D18: anonymous | F18: 18 - 24 | G18: High school | H18: No | I18: Hybrid | J18: 2 | K18: finance | L18: 101–500 | M18: Less than 1 year | N18: Tester | O18: 4–7 people | P18: Short-term / contract project; | Q18: I understand the definition of interruption | R18: 7–10 times | S18: 3 | T18: Team chats and messages (e.g., Teams, Slack, Jira); | U18: Requests for help with environment issues; | V18: Other departments (HR, sales, marketing) | W18: 3 | X18: 1 - 15 minutes | Y18: 2 | Z18: 30 - 60 minutes | AA18: No | AD18: 4 | AE18: 2 | AF18: 3 | AG18: idk | AH18: idk | AI18: idk | AJ18: No
A19: 18 | B19: 45998.8 | C19: 45998.803 | D19: anonymous | F19: 18 - 24 | G19: High school | H19: No | I19: Remote | J19: 1 | K19: Insurances | L19: More than 5000 | M19: 1–3 years | N19: IT Consultant | O19: More than 20 people | P19: Short-term / contract project; | Q19: I understand the definition of interruption | R19: 3–6 times | S19: 2 | T19: Meetings and quick conversations (e.g., ad-hoc calls, unexpected discussions); | U19: Requests for help with environment issues; | V19: Colleagues at the same level (team members / peers) | W19: 3 | X19: 1 - 15 minutes | Y19: 2 | Z19: 1 - 15 minutes | AA19: Yes | AB19: Do not disturb mode, delaying less important task | AC19: 4 | AD19: 4 | AE19: 2 | AF19: 5 | AG19: Get a remote job | AH19: Interuptions are not really avoidable | AI19: Interruptions are not really avoidable | AJ19: No
A20: 19 | B20: 45998.805 | C20: 45998.808 | D20: anonymous | F20: 18 - 24 | G20: Bachelor’s degree | H20: Yes | I20: On-site | J20: 3 | K20: finance | L20: Under 20 employees | M20: 1–3 years | N20: IT Manager | O20: 2–3 people | P20: Internal product (e.g., company systems); | Q20: I understand the definition of interruption | R20: Less than 3 times per day | S20: 1 | T20: Meetings and quick conversations (e.g., ad-hoc calls, unexpected discussions); | U20: Technical questions or code questions; | V20: Client / end user | W20: 4 | X20: 15 - 30 minutes | Y20: 3 | Z20: 15 - 30 minutes | AA20: Sometimes | AB20: lock the door | AC20: 4 | AD20: 4 | AE20: 3 | AF20: 4 | AG20: idk | AJ20: No
A21: 20 | B21: 45999.333 | C21: 45999.337 | D21: anonymous | F21: 30 - 34 | G21: Master’s degree | H21: Yes | I21: Hybrid | J21: 2 | K21: Data Science | L21: More than 5000 | M21: 8–12 years | N21: Data Scientist | O21: 8–12 people | P21: Internal product (e.g., company systems); | Q21: I understand the definition of interruption | R21: 3–6 times | S21: 2 | T21: Team chats and messages (e.g., Teams, Slack, Jira);Meetings and quick conversations (e.g., ad-hoc calls, unexpected discussions);Work environment (e.g., office noise, conversations, working on multiple projects simultaneously); | U21: Implementation details;Technical questions or code questions;Notifications from communication tools;Organizational matters (e.g., meetings, planning); | V21: Colleagues at the same level (team members / peers) | W21: 4 | X21: 30 - 60 minutes | Y21: 4 | Z21: 15 - 30 minutes | AA21: Sometimes | AB21: Wyciszenie powiadomień, nie branie udziału w zbędnych spotkaniach | AC21: 4 | AD21: 5 | AE21: 4 | AF21: 4 | AJ21: No
A22: 21 | B22: 45999.511 | C22: 45999.517 | D22: anonymous | F22: 45 - 54 | G22: Master’s degree | H22: Yes | I22: Hybrid | J22: 2 | K22: finance | L22: More than 5000 | M22: 4–7 years | N22: Product & Proces Development Expert | O22: 13–20 people | P22: Commercial product (external client); | Q22: I understand the definition of interruption | R22: 3–6 times | S22: 2 | T22: Team chats and messages (e.g., Teams, Slack, Jira);Meetings and quick conversations (e.g., ad-hoc calls, unexpected discussions);Work environment (e.g., office noise, conversations, working on multiple projects simultaneously); | U22: Organizational matters (e.g., meetings, planning);Notifications from communication tools;Task status reminders; | V22: Colleagues at the same level (team members / peers) | W22: 3 | X22: 1 - 15 minutes | Y22: 2 | Z22: 1 - 15 minutes | AA22: No | AD22: 4 | AE22: 2 | AF22: 4 | AJ22: No
A23: 22 | B23: 45999.626 | C23: 45999.628 | D23: anonymous | F23: 18 - 24 | G23: Bachelor’s degree | H23: Yes | I23: Hybrid | J23: 2 | K23: Home devices | L23: More than 5000 | M23: 1–3 years | N23: Developer | O23: 4–7 people | P23: Internal product (e.g., company systems); | Q23: I understand the definition of interruption | R23: 3–6 times | S23: 2 | T23: Team chats and messages (e.g., Teams, Slack, Jira);Self-interruptions (voluntary context switching) — switching tasks on your own initiative (e.g., technical blockage, loss of focus); | U23: Technical questions or code questions;Organizational matters (e.g., meetings, planning); | V23: Colleagues at the same level (team members / peers) | W23: 3 | X23: Immediately | Y23: 1 | Z23: 1 - 15 minutes | AA23: No | AD23: 4 | AE23: 3 | AF23: 5 | AJ23: No
A24: 23 | B24: 45999.66 | C24: 45999.662 | D24: anonymous | F24: 18 - 24 | G24: Bachelor’s degree | H24: Yes | I24: Hybrid | J24: 2 | K24: Consulting | L24: More than 5000 | M24: 1–3 years | N24: Developer | O24: 8–12 people | P24: Short-term / contract project; | Q24: I understand the definition of interruption | R24: More than 10 times | S24: 4 | T24: Team chats and messages (e.g., Teams, Slack, Jira);Meetings and quick conversations (e.g., ad-hoc calls, unexpected discussions);System notifications and emails (alerts, reminders, work messages);Self-interruptions (voluntary context switching) — switching tasks on your own initiative (e.g., technical blockage, loss of focus); | U24: Notifications from communication tools;Task status reminders;Organizational matters (e.g., meetings, planning); | V24: Colleagues at the same level (team members / peers) | W24: 3 | X24: 1 - 15 minutes | Y24: 2 | Z24: 15 - 30 minutes | AA24: No | AD24: 4 | AE24: 3 | AF24: 4 | AJ24: No
A25: 24 | B25: 45999.681 | C25: 45999.682 | D25: anonymous | F25: 18 - 24 | G25: Bachelor’s degree | H25: Yes | I25: Remote | J25: 1 | K25: Enterprise | L25: 501–5000 | M25: 1–3 years | N25: Developer | O25: 4–7 people | P25: Commercial product (external client); | Q25: I understand the definition of interruption | R25: 3–6 times | S25: 2 | T25: Team chats and messages (e.g., Teams, Slack, Jira);System notifications and emails (alerts, reminders, work messages);Self-interruptions (voluntary context switching) — switching tasks on your own initiative (e.g., technical blockage, loss of focus); | U25: Code review;Requests for help with environment issues;Notifications from communication tools;Task status reminders;Organizational matters (e.g., meetings, planning); | V25: Colleagues at the same level (team members / peers) | W25: 2 | X25: 1 - 15 minutes | Y25: 2 | Z25: 1 - 15 minutes | AA25: No | AD25: 2 | AE25: 2 | AF25: 3 | AJ25: No
A26: 25 | B26: 45999.681 | C26: 45999.689 | D26: anonymous | F26: 18 - 24 | G26: Bachelor’s degree | H26: Yes | I26: On-site | J26: 3 | K26: Software development (smaller projects) | L26: 21–100 | M26: 1–3 years | N26: Developer | O26: 8–12 people | P26: Internal product (e.g., company systems);Commercial product (external client);Short-term / contract project; | Q26: I understand the definition of interruption | R26: 7–10 times | S26: 3 | T26: Work environment (e.g., office noise, conversations, working on multiple projects simultaneously);Self-interruptions (voluntary context switching) — switching tasks on your own initiative (e.g., technical blockage, loss of focus);Team chats and messages (e.g., Teams, Slack, Jira);Meetings and quick conversations (e.g., ad-hoc calls, unexpected discussions); | U26: Technical questions or code questions;Requests for help with environment issues;Implementation details; | V26: Colleagues at the same level (team members / peers) | W26: 4 | X26: Immediately | Y26: 1 | Z26: 1 - 15 minutes | AA26: Sometimes | AB26: Usually weating headphones means "i'm working" and my colleagues are used to me not listening them at all when i have them on. | AC26: 2 | AD26: 3 | AE26: 4 | AF26: 4 | AG26: Maybe somehow condition my teammates that i will not fix every problem at hand, start working remotely. | AH26: Enforce increasing task estimates after each interruption (management will see how much it can slow the work down), somehow enforce that many interruptions derive from poor documentation? if somebody asks you hows does it work it means you did not describe it properly. | AI26: I'd prefer the higher ups would not interfere in this. Maybe a middle manager could say something here. | AJ26: Yes | AK26: hubisoroka@gmail.com
A27: 26 | B27: 45999.738 | C27: 45999.741 | D27: anonymous | F27: 18 - 24 | G27: Bachelor’s degree | H27: Yes | I27: Remote | J27: 1 | K27: Finance | L27: 501–5000 | M27: 4–7 years | N27: Developer | O27: 4–7 people | P27: Internal product (e.g., company systems);Research & development (R&D); | Q27: I understand the definition of interruption | R27: 3–6 times | S27: 2 | T27: Team chats and messages (e.g., Teams, Slack, Jira);Meetings and quick conversations (e.g., ad-hoc calls, unexpected discussions);System notifications and emails (alerts, reminders, work messages);Self-interruptions (voluntary context switching) — switching tasks on your own initiative (e.g., technical blockage, loss of focus); | U27: Technical questions or code questions;Requests for help with environment issues;Code review;Notifications from communication tools;Organizational matters (e.g., meetings, planning); | V27: People in supporting or junior roles (e.g., less experienced team members) | W27: 3 | X27: 1 - 15 minutes | Y27: 2 | Z27: 1 - 15 minutes | AA27: No | AD27: 4 | AE27: 2 | AF27: 4 | AJ27: No
A28: 27 | B28: 45999.785 | C28: 45999.789 | D28: anonymous | F28: 18 - 24 | G28: Bachelor’s degree | H28: Yes | I28: Hybrid | J28: 2 | K28: embedded | L28: 101–500 | M28: 1–3 years | N28: Developer | O28: 8–12 people | P28: Commercial product (external client); | Q28: I understand the definition of interruption | R28: 3–6 times | S28: 2 | T28: Team chats and messages (e.g., Teams, Slack, Jira);Meetings and quick conversations (e.g., ad-hoc calls, unexpected discussions);Self-interruptions (voluntary context switching) — switching tasks on your own initiative (e.g., technical blockage, loss of focus); | U28: Requests for help with environment issues;Technical questions or code questions; | V28: Colleagues at the same level (team members / peers) | W28: 2 | X28: Immediately | Y28: 1 | Z28: 15 - 30 minutes | AA28: No | AD28: 3 | AE28: 2 | AF28: 3 | AJ28: No
A29: 28 | B29: 45999.874 | C29: 45999.887 | D29: anonymous | F29: 18 - 24 | G29: Bachelor’s degree | H29: Yes | I29: Remote | J29: 1 | K29: enterprise software | L29: 101–500 | M29: 1–3 years | N29: Developer | O29: 13–20 people | P29: Commercial product (external client); | Q29: I understand the definition of interruption | R29: 7–10 times | S29: 3 | T29: Team chats and messages (e.g., Teams, Slack, Jira);System notifications and emails (alerts, reminders, work messages); | U29: Requests for help with environment issues;Notifications from communication tools;Jira ticket status updates from clients; | V29: Client / end user | W29: 5 | X29: Immediately | Y29: 1 | Z29: 1 - 15 minutes | AA29: Sometimes | AB29: 1. transparency about my workload. When people know i have a lot to do they tend to interrupt me less often. 2. Not responding immediately after receiving a notification. | AC29: 4 | AD29: 4 | AE29: 5 | AF29: 4 | AG29: Change the job, because working in anything maintenance related is all about interruptions. | AH29: aggregate messages and send them less frequently | AI29: silent hours, tasks workflow change | AJ29: No
A30: 29 | B30: 45999.91 | C30: 45999.913 | D30: anonymous | F30: 18 - 24 | G30: Bachelor’s degree | H30: Yes | I30: Hybrid | J30: 2 | K30: CultureTech | L30: Under 20 employees | M30: 4–7 years | N30: Tech Lead | O30: 2–3 people | P30: Internal product (e.g., company systems);Commercial product (external client); | Q30: I understand the definition of interruption | R30: More than 10 times | S30: 4 | T30: System notifications and emails (alerts, reminders, work messages);Self-interruptions (voluntary context switching) — switching tasks on your own initiative (e.g., technical blockage, loss of focus);Work environment (e.g., office noise, conversations, working on multiple projects simultaneously); | U30: Organizational matters (e.g., meetings, planning);Technical questions or code questions;Implementation details;Requests for help with environment issues; | V30: Colleagues at the same level (team members / peers) | W30: 3 | X30: 1 - 15 minutes | Y30: 2 | Z30: 30 - 60 minutes | AA30: Yes | AB30: I just ignoring them or whenever I am taking sudden event, I am repeating in my mind "remember what were you doing just seconds ago" | AC30: 3 | AD30: 3 | AE30: 3 | AF30: 3 | AG30: Invest more into organisation/hr or assistant | AH30: Better time management and structure | AI30: Invest more into organisation/hr or assistant | AJ30: No
A31: 30 | B31: 46000.769 | C31: 46000.771 | D31: anonymous | F31: 18 - 24 | G31: Bachelor’s degree | H31: Yes | I31: Remote | J31: 1 | K31: IT assets management | L31: 21–100 | M31: 1–3 years | N31: Tester | O31: 4–7 people | P31: Internal product (e.g., company systems); | Q31: I understand the definition of interruption | R31: More than 10 times | S31: 4 | T31: Team chats and messages (e.g., Teams, Slack, Jira);Self-interruptions (voluntary context switching) — switching tasks on your own initiative (e.g., technical blockage, loss of focus);Work environment (e.g., office noise, conversations, working on multiple projects simultaneously); | U31: Requests for help with environment issues; | V31: Colleagues at the same level (team members / peers) | W31: 4 | X31: 1 - 15 minutes | Y31: 2 | Z31: 1 - 15 minutes | AA31: No | AD31: 3 | AE31: 4 | AF31: 4 | AJ31: Yes | AK31: adam.sudol36@gmail.com
A32: 31 | B32: 46000.849 | C32: 46000.855 | D32: anonymous | F32: 25 - 29 | G32: Master’s degree | H32: Yes | I32: Remote | J32: 1 | K32: data engineering | L32: 101–500 | M32: 1–3 years | N32: Developer | O32: 4–7 people | P32: Internal product (e.g., company systems); | Q32: I understand the definition of interruption | R32: Less than 3 times per day | S32: 1 | T32: Team chats and messages (e.g., Teams, Slack, Jira);Meetings and quick conversations (e.g., ad-hoc calls, unexpected discussions);Self-interruptions (voluntary context switching) — switching tasks on your own initiative (e.g., technical blockage, loss of focus); | U32: Technical questions or code questions;Implementation details; | V32: Colleagues at the same level (team members / peers) | W32: 3 | X32: 1 - 15 minutes | Y32: 2 | Z32: 1 - 15 minutes | AA32: No | AD32: 2 | AE32: 2 | AF32: 5 | AG32: 1. Add focus time 2. ignore messages until the task is finished or at least handled (not always possible) 3. Give better updated to my team so that they don't ask so many questions unnecessarily | AH32: 1. Refer to the documentation instead of texting 2. Prepare better before requesting something | AI32: Not sure, most interruptions come from colleagues directly. Maybe limit the overall number of meetings | AJ32: No
A33: 32 | B33: 46002.4 | C33: 46002.405 | D33: anonymous | F33: 45 - 54 | G33: Master’s degree | H33: No | I33: Hybrid | J33: 2 | K33: IT, bankowość | L33: Under 20 employees | M33: More than 12 years | N33: IT Consultant | O33: 8–12 people | P33: Internal product (e.g., company systems);Short-term / contract project; | Q33: I understand the definition of interruption | R33: More than 10 times | S33: 4 | T33: Team chats and messages (e.g., Teams, Slack, Jira);Meetings and quick conversations (e.g., ad-hoc calls, unexpected discussions);System notifications and emails (alerts, reminders, work messages);Self-interruptions (voluntary context switching) — switching tasks on your own initiative (e.g., technical blockage, loss of focus);Work environment (e.g., office noise, conversations, working on multiple projects simultaneously); | U33: Technical questions or code questions;Implementation details;Code review;Notifications from communication tools;Task status reminders;Organizational matters (e.g., meetings, planning); | V33: Colleagues at the same level (team members / peers) | W33: 3 | X33: 1 - 15 minutes | Y33: 2 | Z33: 1 - 15 minutes | AA33: No | AD33: 4 | AE33: 2 | AF33: 5 | AJ33: No
A34: 33 | B34: 46002.64 | C34: 46002.641 | D34: anonymous | F34: 30 - 34 | G34: Master’s degree | H34: No | I34: Hybrid | J34: 2 | K34: Finance & business | L34: More than 5000 | M34: 4–7 years | N34: IT Manager | O34: 13–20 people | P34: Internal product (e.g., company systems); | Q34: I understand the definition of interruption | R34: More than 10 times | S34: 4 | T34: Team chats and messages (e.g., Teams, Slack, Jira); | U34: Organizational matters (e.g., meetings, planning);Notifications from communication tools; | V34: Senior colleagues | W34: 4 | X34: 30 - 60 minutes | Y34: 4 | Z34: 30 - 60 minutes | AA34: No | AD34: 3 | AE34: 4 | AF34: 4 | AJ34: No
A35: 34 | B35: 46002.648 | C35: 46002.651 | D35: anonymous | F35: 30 - 34 | G35: Master’s degree | H35: Yes | I35: Hybrid | J35: 2 | K35: finance | L35: 501–5000 | M35: 8–12 years | N35: Developer | O35: 13–20 people | P35: Commercial product (external client); | Q35: I understand the definition of interruption | R35: 3–6 times | S35: 2 | T35: Work environment (e.g., office noise, conversations, working on multiple projects simultaneously);Team chats and messages (e.g., Teams, Slack, Jira);Meetings and quick conversations (e.g., ad-hoc calls, unexpected discussions); | U35: Organizational matters (e.g., meetings, planning);Technical questions or code questions; | V35: Colleagues at the same level (team members / peers) | W35: 2 | X35: 1 - 15 minutes | Y35: 2 | Z35: 15 - 30 minutes | AA35: No | AD35: 4 | AE35: 2 | AF35: 4 | AJ35: No
A36: 35 | B36: 46003.308 | C36: 46003.311 | D36: anonymous | F36: 30 - 34 | G36: High school | H36: Yes | I36: Remote | J36: 1 | K36: finance | L36: More than 5000 | M36: 8–12 years | N36: Tester | O36: More than 20 people | P36: Internal product (e.g., company systems);Commercial product (external client); | Q36: I understand the definition of interruption | R36: 7–10 times | S36: 3 | T36: Team chats and messages (e.g., Teams, Slack, Jira);Meetings and quick conversations (e.g., ad-hoc calls, unexpected discussions); | U36: Technical questions or code questions;Requests for help with environment issues; | V36: Colleagues at the same level (team members / peers) | W36: 5 | X36: 1 - 15 minutes | Y36: 2 | Z36: more than 60 minutes | AA36: No | AD36: 4 | AE36: 4 | AF36: 3 | AG36: More skilled workforce | AH36: know their role and learn systems they're working on | AI36: more work, less talk | AJ36: No
A37: 36 | B37: 46005.476 | C37: 46005.482 | D37: anonymous | F37: 45 - 54 | G37: Master’s degree | H37: Yes | I37: Hybrid | J37: 2 | K37: Telecom | L37: More than 5000 | M37: 8–12 years | N37: IT Manager | O37: 2–3 people | P37: Internal product (e.g., company systems); | Q37: I understand the definition of interruption | R37: Less than 3 times per day | S37: 1 | T37: Team chats and messages (e.g., Teams, Slack, Jira);Meetings and quick conversations (e.g., ad-hoc calls, unexpected discussions);System notifications and emails (alerts, reminders, work messages); | U37: Technical questions or code questions;Organizational matters (e.g., meetings, planning); | V37: Colleagues at the same level (team members / peers) | W37: 3 | X37: Immediately | Y37: 1 | Z37: 1 - 15 minutes | AA37: No | AD37: 5 | AE37: 4 | AF37: 5 | AG37: Set "do not interrupt" status | AH37: Better knowledge of documentation, consulting the documentation prior to interrupting | AI37: Introduce "Hyde Park time" - period in a workday where questions can be asked and eventual interruptions are more likely | AJ37: No
A38: 37 | B38: 46007.546 | C38: 46007.569 | D38: anonymous | F38: 25 - 29 | G38: Master’s degree | H38: Yes | I38: Hybrid | J38: 2 | K38: Finance | L38: More than 5000 | M38: 1–3 years | N38: Developer | O38: 8–12 people | P38: Internal product (e.g., company systems); | Q38: I understand the definition of interruption | R38: 3–6 times | S38: 2 | T38: Meetings and quick conversations (e.g., ad-hoc calls, unexpected discussions);Team chats and messages (e.g., Teams, Slack, Jira);System notifications and emails (alerts, reminders, work messages);Self-interruptions (voluntary context switching) — switching tasks on your own initiative (e.g., technical blockage, loss of focus); | U38: Technical questions or code questions;Code review;Requests for help with environment issues;Notifications from communication tools;Organizational matters (e.g., meetings, planning); | V38: Colleagues at the same level (team members / peers) | W38: 2 | X38: Immediately | Y38: 1 | Z38: 1 - 15 minutes | AA38: No | AD38: 4 | AE38: 2 | AF38: 4 | AG38: Reserve daily time slot for code reviews; verify your calendar at the beginning of the day; react as soon as possible to avoid cumulatimg those tasks | AH38: First verify (something) on your own and ask for help after that; dont accumulate extra things to do like f.e. code reviews, tickets testimg etc; react asap | AI38: Dont spam too much on mailbox with mails not related to my departament/position. Mimizie the amount of „unnecessary” meetings | AJ38: Yes | AK38: pilacki.lukasz@gmail.com
A39: 38 | B39: 46007.676 | C39: 46007.684 | D39: anonymous | F39: 18 - 24 | G39: Bachelor’s degree | H39: No | I39: Remote | J39: 1 | K39: technology consulting, IT projects (mainly Data/AI) | L39: More than 5000 | M39: Less than 1 year | N39: Data Analyst | O39: 13–20 people | P39: Commercial product (external client); | Q39: I understand the definition of interruption | R39: 7–10 times | S39: 3 | T39: Team chats and messages (e.g., Teams, Slack, Jira);Meetings and quick conversations (e.g., ad-hoc calls, unexpected discussions);System notifications and emails (alerts, reminders, work messages); | U39: Organizational matters (e.g., meetings, planning);Technical questions or code questions;Requests for help with environment issues;Notifications from communication tools; | V39: Colleagues at the same level (team members / peers) | W39: 4 | X39: 1 - 15 minutes | Y39: 2 | Z39: 15 - 30 minutes | AA39: No | AD39: 4 | AE39: 4 | AF39: 3 | AG39: set status to busy and turn off notifications | AH39: raise on the daily morning that they will need my help later and schedule it in calendar | AJ39: No
A40: 39 | B40: 46009.381 | C40: 46009.442 | D40: anonymous | F40: 18 - 24 | G40: Bachelor’s degree | H40: Yes | I40: Hybrid | J40: 2 | K40: Software for Universities | L40: 21–100 | M40: 1–3 years | N40: Developer | O40: 4–7 people | P40: Commercial product (external client); | Q40: I understand the definition of interruption | R40: Less than 3 times per day | S40: 1 | T40: Team chats and messages (e.g., Teams, Slack, Jira);Meetings and quick conversations (e.g., ad-hoc calls, unexpected discussions); | U40: Technical questions or code questions;Implementation details;Requests for help with environment issues; | V40: Most often I am the one who interrupts others by asking questions | W40: 2 | X40: Immediately | Y40: 1 | Z40: 1 - 15 minutes | AA40: No | AD40: 3 | AE40: 1 | AF40: 4 | AG40: Mute notifications, | AH40: Set rules about, when we can discuss things; | AI40: Limit the number of not necessary meetings, make rooms noise proof to reduce noise from other parts of office i.e. Kitchen | AJ40: No
...

Sheet wybrane kolumny do analiz
A1: Id | B1: Frequency_ordinal | C1: disruptiveness | E1: Id | F1: Time_to_regain_focus_ordinal | G1: disruptiveness | I1: Id | J1: disruptiveness | K1: productivity | M1: Id | N1: disruptiveness | O1: satisfaction | Q1: Id | R1: work arrangement | S1: disruptiveness | T1: work arrangement ordinal
A2: 1 | B2: 2 | C2: 2 | E2: 1 | F2: 2 | G2: 2 | I2: 1 | J2: 2 | K2: 3 | M2: 1 | N2: 2 | O2: 3 | Q2: 1 | R2: Hybrid | S2: 2 | T2: 2
A3: 2 | B3: 2 | C3: 2 | E3: 2 | F3: 2 | G3: 2 | I3: 2 | J3: 2 | K3: 4 | M3: 2 | N3: 2 | O3: 4 | Q3: 2 | R3: Hybrid | S3: 2 | T3: 2
A4: 3 | B4: 1 | C4: 4 | E4: 3 | F4: 2 | G4: 4 | I4: 3 | J4: 4 | K4: 5 | M4: 3 | N4: 4 | O4: 5 | Q4: 3 | R4: On-site | S4: 4 | T4: 3
A5: 4 | B5: 1 | C5: 4 | E5: 4 | F5: 2 | G5: 4 | I5: 4 | J5: 4 | K5: 4 | M5: 4 | N5: 4 | O5: 2 | Q5: 4 | R5: Hybrid | S5: 4 | T5: 2
A6: 5 | B6: 2 | C6: 3 | E6: 5 | F6: 2 | G6: 3 | I6: 5 | J6: 3 | K6: 3 | M6: 5 | N6: 3 | O6: 4 | Q6: 5 | R6: Hybrid | S6: 3 | T6: 2
A7: 6 | B7: 1 | C7: 3 | E7: 6 | F7: 2 | G7: 3 | I7: 6 | J7: 3 | K7: 3 | M7: 6 | N7: 3 | O7: 4 | Q7: 6 | R7: Hybrid | S7: 3 | T7: 2
A8: 7 | B8: 3 | C8: 4 | E8: 7 | F8: 2 | G8: 4 | I8: 7 | J8: 4 | K8: 3 | M8: 7 | N8: 4 | O8: 2 | Q8: 7 | R8: Remote | S8: 4 | T8: 1
A9: 8 | B9: 4 | C9: 4 | E9: 8 | F9: 2 | G9: 4 | I9: 8 | J9: 4 | K9: 4 | M9: 8 | N9: 4 | O9: 5 | Q9: 8 | R9: Remote | S9: 4 | T9: 1
A10: 9 | B10: 2 | C10: 3 | E10: 9 | F10: 4 | G10: 3 | I10: 9 | J10: 3 | K10: 4 | M10: 9 | N10: 3 | O10: 4 | Q10: 9 | R10: Hybrid | S10: 3 | T10: 2
A11: 10 | B11: 2 | C11: 5 | E11: 10 | F11: 2 | G11: 5 | I11: 10 | J11: 5 | K11: 4 | M11: 10 | N11: 5 | O11: 4 | Q11: 10 | R11: Remote | S11: 5 | T11: 1
A12: 11 | B12: 3 | C12: 4 | E12: 11 | F12: 2 | G12: 4 | I12: 11 | J12: 4 | K12: 4 | M12: 11 | N12: 4 | O12: 4 | Q12: 11 | R12: On-site | S12: 4 | T12: 3
A13: 12 | B13: 2 | C13: 3 | E13: 12 | F13: 2 | G13: 3 | I13: 12 | J13: 3 | K13: 4 | M13: 12 | N13: 3 | O13: 4 | Q13: 12 | R13: Hybrid | S13: 3 | T13: 2
... A75: 74 | B75: 2 | C75: 3 | E75: 74 | F75: 2 | G75: 3 | I75: 74 | J75: 3 | K75: 4 | M75: 74 | N75: 3 | O75: 4 | Q75: 74 | R75: Hybrid | S75: 3 | T75: 2

Sheet Wielokrotny wybor rozbite
A1: Id | B1: What are the most common sources of interruptions in your work? | D1: Id | E1: InterruptionSource | G1: Id | H1: What are these interruptions usually about? | K1: Id | L1: Category
A2: 1 | B2: Team chats and messages (e.g., Teams, Slack, Jira);Meetings and quick conversations (e.g., ad-hoc calls, unexpected discussions); | D2: 1 | E2: Team chats and messages | G2: 1 | H2: Implementation details; | K2: 1 | L2: Implementation details
A3: 2 | B3: Team chats and messages (e.g., Teams, Slack, Jira);Meetings and quick conversations (e.g., ad-hoc calls, unexpected discussions);System notifications and emails (alerts, reminders, work messages);Self-interruptions (voluntary context switching) — switching tasks on your own initiative (e.g., technical blockage, loss of focus); | D3: 1 | E3: Meetings and quick conversations | G3: 2 | H3: Technical questions or code questions;Notifications from communication tools;Organizational matters (e.g., meetings, planning); | K3: 2 | L3: Technical questions or code questions
A4: 3 | B4: Meetings and quick conversations (e.g., ad-hoc calls, unexpected discussions); | D4: 2 | E4: Team chats and messages | G4: 3 | H4: Code review; | K4: 2 | L4: Notifications from communication tools
A5: 4 | B5: Team chats and messages (e.g., Teams, Slack, Jira);Work environment (e.g., office noise, conversations, working on multiple projects simultaneously); | D5: 2 | E5: Meetings and quick conversations | G5: 4 | H5: Requests for help with environment issues; | K5: 2 | L5: Organizational matters (e.g., meetings, planning)
A6: 5 | B6: Team chats and messages (e.g., Teams, Slack, Jira); | D6: 2 | E6: System notifications and emails | G6: 5 | H6: Implementation details; | K6: 3 | L6: Code review
A7: 6 | B7: Meetings and quick conversations (e.g., ad-hoc calls, unexpected discussions);Team chats and messages (e.g., Teams, Slack, Jira); | D7: 2 | E7: Self-interruptions | G7: 6 | H7: Notifications from communication tools;Requests for help with environment issues; | K7: 4 | L7: Requests for help with environment issues
A8: 7 | B8: Team chats and messages (e.g., Teams, Slack, Jira);System notifications and emails (alerts, reminders, work messages);Work environment (e.g., office noise, conversations, working on multiple projects simultaneously); | D8: 3 | E8: Meetings and quick conversations | G8: 7 | H8: Implementation details;Notifications from communication tools; | K8: 5 | L8: Implementation details
A9: 8 | B9: Team chats and messages (e.g., Teams, Slack, Jira);Meetings and quick conversations (e.g., ad-hoc calls, unexpected discussions);System notifications and emails (alerts, reminders, work messages); | D9: 4 | E9: Team chats and messages | G9: 8 | H9: Technical questions or code questions;Implementation details;Requests for help with environment issues;Code review;Notifications from communication tools;Organizational matters (e.g., meetings, planning); | K9: 6 | L9: Notifications from communication tools
A10: 9 | B10: Meetings and quick conversations (e.g., ad-hoc calls, unexpected discussions);System notifications and emails (alerts, reminders, work messages);Team chats and messages (e.g., Teams, Slack, Jira); | D10: 4 | E10: Work environment | G10: 9 | H10: Task status reminders;Requests for help with environment issues;Implementation details; | K10: 6 | L10: Requests for help with environment issues
A11: 10 | B11: System notifications and emails (alerts, reminders, work messages); | D11: 5 | E11: Team chats and messages | G11: 10 | H11: Implementation details; | K11: 7 | L11: Implementation details
A12: 11 | B12: Team chats and messages (e.g., Teams, Slack, Jira);System notifications and emails (alerts, reminders, work messages);Self-interruptions (voluntary context switching) — switching tasks on your own initiative (e.g., technical blockage, loss of focus); | D12: 6 | E12: Meetings and quick conversations | G12: 11 | H12: Technical questions or code questions; | K12: 7 | L12: Notifications from communication tools
A13: 12 | B13: Team chats and messages (e.g., Teams, Slack, Jira);Self-interruptions (voluntary context switching) — switching tasks on your own initiative (e.g., technical blockage, loss of focus); | D13: 6 | E13: Team chats and messages | G13: 12 | H13: Task status reminders;Organizational matters (e.g., meetings, planning); | K13: 8 | L13: Technical questions or code questions
... A75: 74 | B75: Team chats and messages (e.g., Teams, Slack, Jira);Meetings and quick conversations (e.g., ad-hoc calls, unexpected discussions);System notifications and emails (alerts, reminders, work messages) | D75: 32 | E75: Team chats and messages | G75: 74 | H75: Organizational matters (e.g., meetings, planning);Notifications from communication tools | K75: 32 | L75: Code review
D76: 32 | E76: Meetings and quick conversations | K76: 32 | L76: Notifications from communication tools
D77: 32 | E77: System notifications and emails | K77: 32 | L77: Task status reminders
D78: 32 | E78: Self-interruptions | K78: 32 | L78: Organizational matters (e.g., meetings, planning)
D79: 32 | E79: Work environment | K79: 33 | L79: Organizational matters (e.g., meetings, planning)
D80: 33 | E80: Team chats and messages | K80: 33 | L80: Notifications from communication tools
D81: 34 | E81: Work environment | K81: 34 | L81: Organizational matters (e.g., meetings, planning)
D82: 34 | E82: Team chats and messages | K82: 34 | L82: Technical questions or code questions
D83: 34 | E83: Meetings and quick conversations | K83: 35 | L83: Technical questions or code questions
D84: 35 | E84: Team chats and messages | K84: 35 | L84: Requests for help with environment issues
D85: 35 | E85: Meetings and quick conversations | K85: 36 | L85: Technical questions or code questions
D86: 36 | E86: Team chats and messages | K86: 36 | L86: Organizational matters (e.g., meetings, planning)
D87: 36 | E87: Meetings and quick conversations | K87: 37 | L87: Technical questions or code questions
... D210: 73 | E210: Meetings and quick conversations | K210: 74 | L210: Notifications from communication tools
D211: 74 | E211: Team chats and messages
D212: 74 | E212: Meetings and quick conversations
D213: 74 | E213: System notifications and emails

Sheet Open q1 labeled
A1: Question | B1: In which industry/domain does your company operate (e.g., finance, game development, enterprise software)?
A2: ID | B2: Answer | C2: Label
A3: 1 | B3: Finanance | C3: Finance
A4: 2 | B4: FINANCE | C4: Finance
A5: 3 | B5: Finance | C5: Finance
A6: 4 | B6: Office | C6: Enterprise Software
A7: 5 | B7: Finance | C7: Finance
A8: 6 | B8: finance | C8: Finance
A9: 7 | B9: Finance | C9: Finance
A10: 8 | B10: Game Dev | C10: Game Development
A11: 9 | B11: My company is operating in finance | C11: Finance
A12: 10 | B12: Fiance | C12: Finance
A13: 11 | B13: Finance | C13: Finance
A14: 12 | B14: finance | C14: Finance
... A72: 70 | B72: IT | C72: IT (General)
B76: Etykiety wierszy | C76: Liczba z ID
B77: Finance | C77: 31
B78: IT Services / Consulting | C78: 5
B79: Enterprise Software | C79: 4
B80: Data / AI | C80: 4
B81: Hardware / Embedded | C81: 4
B82: Retail | C82: 2
B83: Software Development | C83: 2
B84: Energy | C84: 1
B85: Other | C85: 1
B86: IT Support | C86: 1
B87: Chemical Engineering | C87: 1
B88: SaaS / Enterprise | C88: 1
... B102: Suma końcowa | C102: 70

Sheet Open q2 labeled
A1: Question | B1: What methods do you personally use to reduce or manage interruptions during your work? (max. 3)
A2: ID | B2: Answer | C2: Label | D2: Effectiveness of methods
A3: 1 | C3: No Strategy Reported | D3: =VLOOKUP(PersonalMethods[[#This Row],[ID]],Data!A:AC,29,FALSE) -> 0
A4: 2 | B4: NOT DISTURB STATUS IN TEAMS, IGNORING MESSAGES AFTER 12 | C4: Availability Signaling | D4: =VLOOKUP(PersonalMethods[[#This Row],[ID]],Data!A:AC,29,FALSE) -> 2
A5: 3 | B5: . | C5: No Strategy Reported | D5: =VLOOKUP(PersonalMethods[[#This Row],[ID]],Data!A:AC,29,FALSE) -> 5
A6: 4 | C6: No Strategy Reported | D6: =VLOOKUP(PersonalMethods[[#This Row],[ID]],Data!A:AC,29,FALSE) -> 0
A7: 5 | C7: No Strategy Reported | D7: =VLOOKUP(PersonalMethods[[#This Row],[ID]],Data!A:AC,29,FALSE) -> 0
A8: 6 | C8: No Strategy Reported | D8: =VLOOKUP(PersonalMethods[[#This Row],[ID]],Data!A:AC,29,FALSE) -> 0
A9: 7 | B9: “do not disturb” | C9: Availability Signaling | D9: =VLOOKUP(PersonalMethods[[#This Row],[ID]],Data!A:AC,29,FALSE) -> 3
A10: 8 | B10: Słuchawki z aktywnym tłumieniem szumów w celu wyciszenia hałasu, sztywne planowanie kolejności wykonywania zadań każdego dnia | C10: Noise Reduction | D10: =VLOOKUP(PersonalMethods[[#This Row],[ID]],Data!A:AC,29,FALSE) -> 4
A11: 8 | B11: Słuchawki z aktywnym tłumieniem szumów w celu wyciszenia hałasu, sztywne planowanie kolejności wykonywania zadań każdego dnia | C11: Task & Priority Management | D11: =VLOOKUP(PersonalMethods[[#This Row],[ID]],Data!A:AC,29,FALSE) -> 4
A12: 9 | C12: No Strategy Reported | D12: =VLOOKUP(PersonalMethods[[#This Row],[ID]],Data!A:AC,29,FALSE) -> 0
A13: 10 | B13: I use the app on my phone | C13: Self-regulation & Autonomy | D13: =VLOOKUP(PersonalMethods[[#This Row],[ID]],Data!A:AC,29,FALSE) -> 4
A14: 11 | C14: No Strategy Reported | D14: =VLOOKUP(PersonalMethods[[#This Row],[ID]],Data!A:AC,29,FALSE) -> 0
A15: 12 | B15: do not disturb | C15: Availability Signaling | D15: =VLOOKUP(PersonalMethods[[#This Row],[ID]],Data!A:AC,29,FALSE) -> 4
A16: 13 | C16: No Strategy Reported | D16: =VLOOKUP(PersonalMethods[[#This Row],[ID]],Data!A:AC,29,FALSE) -> 0
A17: 14 | B17: do not disturb status | C17: Availability Signaling | D17: =VLOOKUP(PersonalMethods[[#This Row],[ID]],Data!A:AC,29,FALSE) -> 3
A18: 15 | C18: No Strategy Reported | D18: =VLOOKUP(PersonalMethods[[#This Row],[ID]],Data!A:AC,29,FALSE) -> 0
A19: 16 | C19: No Strategy Reported | D19: =VLOOKUP(PersonalMethods[[#This Row],[ID]],Data!A:AC,29,FALSE) -> 0
A20: 17 | C20: No Strategy Reported | D20: =VLOOKUP(PersonalMethods[[#This Row],[ID]],Data!A:AC,29,FALSE) -> 0
A21: 18 | B21: Do not disturb mode, delaying less important task | C21: Availability Signaling | D21: =VLOOKUP(PersonalMethods[[#This Row],[ID]],Data!A:AC,29,FALSE) -> 4
A22: 18 | B22: Do not disturb mode, delaying less important task | C22: Task & Priority Management | D22: =VLOOKUP(PersonalMethods[[#This Row],[ID]],Data!A:AC,29,FALSE) -> 4
A23: 19 | B23: lock the door | C23: Physical / Context Isolation | D23: =VLOOKUP(PersonalMethods[[#This Row],[ID]],Data!A:AC,29,FALSE) -> 4
A24: 20 | B24: Wyciszenie powiadomień, nie branie udziału w zbędnych spotkaniach | C24: Availability Signaling | D24: =VLOOKUP(PersonalMethods[[#This Row],[ID]],Data!A:AC,29,FALSE) -> 4
A25: 20 | B25: Wyciszenie powiadomień, nie branie udziału w zbędnych spotkaniach | C25: Calendar & Time Blocking | D25: =VLOOKUP(PersonalMethods[[#This Row],[ID]],Data!A:AC,29,FALSE) -> 4
A26: 21 | C26: No Strategy Reported | D26: =VLOOKUP(PersonalMethods[[#This Row],[ID]],Data!A:AC,29,FALSE) -> 0
A27: 22 | C27: No Strategy Reported | D27: =VLOOKUP(PersonalMethods[[#This Row],[ID]],Data!A:AC,29,FALSE) -> 0
A28: 23 | C28: No Strategy Reported | D28: =VLOOKUP(PersonalMethods[[#This Row],[ID]],Data!A:AC,29,FALSE) -> 0
A29: 24 | C29: No Strategy Reported | D29: =VLOOKUP(PersonalMethods[[#This Row],[ID]],Data!A:AC,29,FALSE) -> 0
A30: 25 | B30: Usually weating headphones means "i'm working" and my colleagues are used to me not listening them at all when i have them on. | C30: Noise Reduction | D30: =VLOOKUP(PersonalMethods[[#This Row],[ID]],Data!A:AC,29,FALSE) -> 2
A31: 26 | C31: No Strategy Reported | D31: =VLOOKUP(PersonalMethods[[#This Row],[ID]],Data!A:AC,29,FALSE) -> 0
A32: 27 | C32: No Strategy Reported | D32: =VLOOKUP(PersonalMethods[[#This Row],[ID]],Data!A:AC,29,FALSE) -> 0
A33: 28 | B33: 1. transparency about my workload. When people know i have a lot to do they tend to interrupt me less often. 2. Not responding immediately after receiving a notification. | C33: Communication Practices | D33: =VLOOKUP(PersonalMethods[[#This Row],[ID]],Data!A:AC,29,FALSE) -> 4
A34: 29 | B34: I just ignoring them or whenever I am taking sudden event, I am repeating in my mind "remember what were you doing just seconds ago" | C34: Self-regulation & Autonomy | D34: =VLOOKUP(PersonalMethods[[#This Row],[ID]],Data!A:AC,29,FALSE) -> 3
A35: 29 | B35: I just ignoring them or whenever I am taking sudden event, I am repeating in my mind "remember what were you doing just seconds ago" | C35: Communication Practices | D35: =VLOOKUP(PersonalMethods[[#This Row],[ID]],Data!A:AC,29,FALSE) -> 3
A36: 30 | C36: No Strategy Reported | D36: =VLOOKUP(PersonalMethods[[#This Row],[ID]],Data!A:AC,29,FALSE) -> 0
A37: 31 | C37: No Strategy Reported | D37: =VLOOKUP(PersonalMethods[[#This Row],[ID]],Data!A:AC,29,FALSE) -> 0
A38: 32 | C38: No Strategy Reported | D38: =VLOOKUP(PersonalMethods[[#This Row],[ID]],Data!A:AC,29,FALSE) -> 0
A39: 33 | C39: No Strategy Reported | D39: =VLOOKUP(PersonalMethods[[#This Row],[ID]],Data!A:AC,29,FALSE) -> 0
A40: 34 | C40: No Strategy Reported | D40: =VLOOKUP(PersonalMethods[[#This Row],[ID]],Data!A:AC,29,FALSE) -> 0
...

Sheet Open q3 labeled
A1: Question | B1: What actions could you take to better manage or reduce unplanned interruptions in your workday? (max 3)
A2: Survey Id | B2: Answer | C2: Label
A3: 1 | C3: No Action / Not Applicable
A4: 2 | C4: No Action / Not Applicable
A5: 3 | C5: No Action / Not Applicable
A6: 4 | C6: No Action / Not Applicable
A7: 5 | B7: Block dedicated focus time on my calendar and mute non-critical notifications during those periods. | C7: Calendar Blocking
A8: 5 | B8: Block dedicated focus time on my calendar and mute non-critical notifications during those periods. | C8: Notification Muting
A9: 5 | B9: Set clearer expectations with colleagues about my availability and preferred communication channels. | C9: Communication Norms
A10: 5 | B10: Prioritize tasks at the start of each day so I can quickly refocus after any unavoidable interruptions | C10: Task Prioritization
A11: 6 | C11: No Action / Not Applicable
A12: 7 | C12: No Action / Not Applicable
A13: 8 | C13: No Action / Not Applicable
A14: 9 | B14: Set clear focus blocks by scheduling dedicated time for deep work and temporarily muting non-urgent notifications. | C14: Calendar Blocking
A15: 9 | B15: Set clear focus blocks by scheduling dedicated time for deep work and temporarily muting non-urgent notifications. | C15: Notification Muting
A16: 10 | B16: I plan my tasks, mute notifications, and set specific times to respond to messages. | C16: Task Planning
A17: 10 | B17: I plan my tasks, mute notifications, and set specific times to respond to messages. | C17: Notification Muting
A18: 10 | B18: I plan my tasks, mute notifications, and set specific times to respond to messages. | C18: Delayed Response
A19: 11 | B19: Turn of my phone | C19: Device Shutdown / Offline
A20: 12 | B20: turn on: do not disturb in my phone | C20: Do Not Disturb / Status
A21: 13 | C21: No Action / Not Applicable
A22: 14 | C22: No Action / Not Applicable
A23: 15 | B23: silence notifications | C23: Notification Muting
A24: 16 | B24: Set dedicated focus time blocks with “Do Not Disturb” enabled to minimize spontaneous interruptions during deep-work tasks. | C24: Calendar Blocking
A25: 16 | B25: Set dedicated focus time blocks with “Do Not Disturb” enabled to minimize spontaneous interruptions during deep-work tasks. | C25: Do Not Disturb / Status
A26: 16 | B26: Improve daily planning and prioritization, including reserving buffer time for unexpected issues to reduce context-switching. | C26: Task Planning
A27: 16 | B27: Communicate availability proactively so teammates know when I’m open for questions and when I need uninterrupted time. | C27: Communication Norms
A28: 17 | B28: idk | C28: No Action / Not Applicable
A29: 18 | B29: Get a remote job | C29: Remote Work
A30: 19 | B30: idk | C30: No Action / Not Applicable
A31: 20 | C31: No Action / Not Applicable
A32: 21 | C32: No Action / Not Applicable
A33: 22 | C33: No Action / Not Applicable
A34: 23 | C34: No Action / Not Applicable
A35: 24 | C35: No Action / Not Applicable
A36: 25 | B36: Maybe somehow condition my teammates that i will not fix every problem at hand, start working remotely. | C36: Boundary Setting
A37: 25 | B37: Maybe somehow condition my teammates that i will not fix every problem at hand, start working remotely. | C37: Remote Work
A38: 26 | C38: No Action / Not Applicable
A39: 27 | C39: No Action / Not Applicable
